<?xml version='1.0' encoding='utf-8'?>
<sdf version="1.11">
	<model name="robot">
		<link name="link11">
			<pose degrees="true">6.55 5.079 2.7175999735764678 180 13.5 0</pose>
			<inertial auto="true">
				<density>1000</density>
			</inertial>
			<collision name="link11colli">
				<geometry>
					<mesh>
						<uri>file://home/cbb/gz_models/robot/cl1.STL</uri>
						<scale>0.1 0.1 0.1</scale>
					</mesh>
				</geometry>
			</collision>
			<visual name="link11visu">
				<geometry>
					<mesh>
						<uri>file://home/cbb/gz_models/robot/cl1.STL</uri>
						<scale>0.1 0.1 0.1</scale>
					</mesh>
				</geometry>
				<material>
					<ambient>1 0 0 1</ambient>
					<diffuse>1 0 0 1</diffuse>
					<specular>1 0 0 1</specular>
				</material>
			</visual>
		</link>
		
		<link name="link1_down">
			<pose degrees="true">6.55 5.079 0 0 166.5 0</pose>
			<inertial auto="true">
				<density>1000</density>
			</inertial>
			<collision name="link1_downcolli">
				<geometry>
					<mesh>
						<uri>file://home/cbb/gz_models/robot/chengg_down.STL</uri>
						<scale>0.1 0.1 0.1</scale>
					</mesh>
				</geometry>
			</collision>
			<visual name="link1_downvisu">
				<geometry>
					<mesh>
						<uri>file://home/cbb/gz_models/robot/chengg_down.STL</uri>
						<scale>0.1 0.1 0.1</scale>
					</mesh>
				</geometry>
				<material>
					<ambient>1 0 0 1</ambient>
					<diffuse>1 0 0 1</diffuse>
					<specular>1 0 0 1</specular>
				</material>
			</visual>
		</link>
	
		<link name="join0">
			<pose degrees="true">0 0 0.0 0 0 0</pose>
			<inertial auto="true">
				<density>1000</density>
			</inertial>
			<collision name="join0colli">
				<geometry>
					<mesh>
						<uri>file://home/cbb/gz_models/robot/jiaol_gan.STL</uri>
						<scale>0.1 0.1 0.1</scale>
					</mesh>
				</geometry>
			</collision>
			<visual name="join0visu">
				<geometry>
					<mesh>
						<uri>file://home/cbb/gz_models/robot/jiaol_gan.STL</uri>
						<scale>0.1 0.1 0.1</scale>
					</mesh>
				</geometry>
				<material>
					<ambient>1 0 0 1</ambient>
					<diffuse>1 0 0 1</diffuse>
					<specular>1 0 0 1</specular>
				</material>
			</visual>
		</link>
		
		<joint name="revjoin11" type="revolute">
			<pose relative_to="link1_down">0 0 0 0 0 0</pose>
			<parent>join0</parent>
			<child>link1_down</child>
			<axis>
				<xyz expressed_in="__model__">0 1 0</xyz>
			</axis>
		</joint>
		
		<frame name="nframe10" attached_to="link1_down">
			<pose relative_to="link1_down">-5.820633849156053 0 0 0 0 0</pose>
		</frame>
		<joint name="crevjoin10" type="revolute">
			<pose relative_to="link1_down">-5.820633849156053 0 0 0 0 0</pose>
			<parent>link11</parent>
			<child>link1_down</child>
			<axis>
				<xyz expressed_in="__model__">0 1 0</xyz>
			</axis>
		</joint>
		
	</model>
</sdf>
